<?xml version="1.0" ?>
<!-- =================================================================================== -->
<!-- |    This document was autogenerated by xacro from /home/aman/depowdering_ws/src/add_post_pro2/depowdering_aman/urdf/depowdering_gripper_robot.xacro | -->
<!-- |    EDITING THIS FILE BY HAND IS NOT RECOMMENDED                                 | -->
<!-- =================================================================================== -->
<robot name="add_post_pro_depowdering">
    <transmission name="trans_1">
        <type>transmission_interface/SimpleTransmission</type>
        <joint name="joint_1">
            <hardwareInterface>hardware_interface/PositionJointInterface</hardwareInterface>
        </joint>
        <actuator name="motor_1">
            <hardwareInterface>hardware_interface/PositionJointInterface</hardwareInterface>
            <mechanicalReduction>1</mechanicalReduction>
        </actuator>
    </transmission>
    <transmission name="trans_2">
        <type>transmission_interface/SimpleTransmission</type>
        <joint name="joint_2">
            <hardwareInterface>hardware_interface/PositionJointInterface</hardwareInterface>
        </joint>
        <actuator name="motor_2">
            <hardwareInterface>hardware_interface/PositionJointInterface</hardwareInterface>
            <mechanicalReduction>1</mechanicalReduction>
        </actuator>
    </transmission>
    <transmission name="trans_3">
        <type>transmission_interface/SimpleTransmission</type>
        <joint name="joint_3">
            <hardwareInterface>hardware_interface/PositionJointInterface</hardwareInterface>
        </joint>
        <actuator name="motor_3">
            <hardwareInterface>hardware_interface/PositionJointInterface</hardwareInterface>
            <mechanicalReduction>1</mechanicalReduction>
        </actuator>
    </transmission>
    <transmission name="trans_4">
        <type>transmission_interface/SimpleTransmission</type>
        <joint name="joint_4">
            <hardwareInterface>hardware_interface/PositionJointInterface</hardwareInterface>
        </joint>
        <actuator name="motor_4">
            <hardwareInterface>hardware_interface/PositionJointInterface</hardwareInterface>
            <mechanicalReduction>1</mechanicalReduction>
        </actuator>
    </transmission>
    <transmission name="trans_5">
        <type>transmission_interface/SimpleTransmission</type>
        <joint name="joint_5">
            <hardwareInterface>hardware_interface/PositionJointInterface</hardwareInterface>
        </joint>
        <actuator name="motor_5">
            <hardwareInterface>hardware_interface/PositionJointInterface</hardwareInterface>
            <mechanicalReduction>1</mechanicalReduction>
        </actuator>
    </transmission>
    <transmission name="trans_6">
        <type>transmission_interface/SimpleTransmission</type>
        <joint name="joint_6">
            <hardwareInterface>hardware_interface/PositionJointInterface</hardwareInterface>
        </joint>
        <actuator name="motor_6">
            <hardwareInterface>hardware_interface/PositionJointInterface</hardwareInterface>
            <mechanicalReduction>1</mechanicalReduction>
        </actuator>
    </transmission>
    <transmission name="trans_gripper_Joint">
        <type>transmission_interface/SimpleTransmission</type>
        <joint name="gripper_Joint">
            <hardwareInterface>hardware_interface/EffortJointInterface</hardwareInterface>
        </joint>
        <actuator name="gripper_Joint_motor">
            <hardwareInterface>hardware_interface/EffortJointInterface</hardwareInterface>
            <mechanicalReduction>1</mechanicalReduction>
        </actuator>
    </transmission>
    <gazebo>
        <plugin filename="libgazebo_ros_control.so" name="gazebo_ros_control">
            <robotNamespace>/add_post_pro_depowdering</robotNamespace>
        </plugin>
    </gazebo>
    <link name="world" />
    <joint name="joint_w" type="fixed">
        <parent link="world" />
        <child link="base_link" />
        <origin xyz="0 0 0" />
    </joint>
    <link name="base_link">
        <visual>
            <origin rpy="0 0 0" xyz="0 0 0" />
            <geometry>
                <mesh filename="package://denso_robot_descriptions/vs6577_description/meshes/base_link.dae" scale="1 1 1" />
            </geometry>
        </visual>
        <collision>
            <origin rpy="0 0 0" xyz="0 0 0" />
            <geometry>
                <mesh filename="package://denso_robot_descriptions/vs6577_description/meshes/base_link.dae" scale="1 1 1" />
            </geometry>
        </collision>
        <inertial>
            <mass value="1" />
            <origin rpy="0.000000 0.000000 0.000000" xyz="0.000000 0.000000 0.000000" />
            <inertia ixx="1" ixy="0" ixz="0" iyy="1" iyz="0" izz="1" />
        </inertial>
    </link>
    <link name="J1">
        <visual>
            <origin rpy="0 0 0" xyz="0 0 0" />
            <geometry>
                <mesh filename="package://denso_robot_descriptions/vs6577_description/meshes/J1.dae" scale="1 1 1" />
            </geometry>
        </visual>
        <collision>
            <origin rpy="0 0 0" xyz="0 0 0" />
            <geometry>
                <mesh filename="package://denso_robot_descriptions/vs6577_description/meshes/J1.dae" scale="1 1 1" />
            </geometry>
        </collision>
        <inertial>
            <mass value="1" />
            <origin rpy="0.000000 0.000000 0.000000" xyz="0.000000 0.000000 0.000000" />
            <inertia ixx="1" ixy="0" ixz="0" iyy="1" iyz="0" izz="1" />
        </inertial>
    </link>
    <link name="J2">
        <visual>
            <origin rpy="0 0 0" xyz="0 0 0" />
            <geometry>
                <mesh filename="package://denso_robot_descriptions/vs6577_description/meshes/J2.dae" scale="1 1 1" />
            </geometry>
        </visual>
        <collision>
            <origin rpy="0 0 0" xyz="0 0 0" />
            <geometry>
                <mesh filename="package://denso_robot_descriptions/vs6577_description/meshes/J2.dae" scale="1 1 1" />
            </geometry>
        </collision>
        <inertial>
            <mass value="1" />
            <origin rpy="0.000000 0.000000 0.000000" xyz="0.000000 0.000000 0.000000" />
            <inertia ixx="1" ixy="0" ixz="0" iyy="1" iyz="0" izz="1" />
        </inertial>
    </link>
    <link name="J3">
        <visual>
            <origin rpy="0 0 0" xyz="0 0 0" />
            <geometry>
                <mesh filename="package://denso_robot_descriptions/vs6577_description/meshes/J3.dae" scale="1 1 1" />
            </geometry>
        </visual>
        <collision>
            <origin rpy="0 0 0" xyz="0 0 0" />
            <geometry>
                <mesh filename="package://denso_robot_descriptions/vs6577_description/meshes/J3.dae" scale="1 1 1" />
            </geometry>
        </collision>
        <inertial>
            <mass value="1" />
            <origin rpy="0.000000 0.000000 0.000000" xyz="0.000000 0.000000 0.000000" />
            <inertia ixx="1" ixy="0" ixz="0" iyy="1" iyz="0" izz="1" />
        </inertial>
    </link>
    <link name="J4">
        <visual>
            <origin rpy="0 0 0" xyz="0 0 0" />
            <geometry>
                <mesh filename="package://denso_robot_descriptions/vs6577_description/meshes/J4.dae" scale="1 1 1" />
            </geometry>
        </visual>
        <collision>
            <origin rpy="0 0 0" xyz="0 0 0" />
            <geometry>
                <mesh filename="package://denso_robot_descriptions/vs6577_description/meshes/J4.dae" scale="1 1 1" />
            </geometry>
        </collision>
        <inertial>
            <mass value="1" />
            <origin rpy="0.000000 0.000000 0.000000" xyz="0.000000 0.000000 0.000000" />
            <inertia ixx="1" ixy="0" ixz="0" iyy="1" iyz="0" izz="1" />
        </inertial>
    </link>
    <link name="J5">
        <visual>
            <origin rpy="0 0 0" xyz="0 0 0" />
            <geometry>
                <mesh filename="package://denso_robot_descriptions/vs6577_description/meshes/J5.dae" scale="1 1 1" />
            </geometry>
        </visual>
        <collision>
            <origin rpy="0 0 0" xyz="0 0 0" />
            <geometry>
                <mesh filename="package://denso_robot_descriptions/vs6577_description/meshes/J5.dae" scale="1 1 1" />
            </geometry>
        </collision>
        <inertial>
            <mass value="1" />
            <origin rpy="0.000000 0.000000 0.000000" xyz="0.000000 0.000000 0.000000" />
            <inertia ixx="1" ixy="0" ixz="0" iyy="1" iyz="0" izz="1" />
        </inertial>
    </link>
    <link name="J6">
        <visual>
            <origin rpy="0 0 0" xyz="0 0 0" />
            <geometry>
                <mesh filename="package://denso_robot_descriptions/vs6577_description/meshes/J6.dae" scale="1 1 1" />
            </geometry>
        </visual>
        <collision>
            <origin rpy="0 0 0" xyz="0 0 0" />
            <geometry>
                <mesh filename="package://denso_robot_descriptions/vs6577_description/meshes/J6.dae" scale="1 1 1" />
            </geometry>
        </collision>
        <inertial>
            <mass value="1" />
            <origin rpy="0.000000 0.000000 0.000000" xyz="0.000000 0.000000 0.000000" />
            <inertia ixx="1" ixy="0" ixz="0" iyy="1" iyz="0" izz="1" />
        </inertial>
    </link>
    <gazebo reference="base_link">
        <material>Gazebo/CoM</material>
    </gazebo>
    <gazebo reference="J1">
        <material>Gazebo/White</material>
    </gazebo>
    <gazebo reference="J2">
        <material>Gazebo/White</material>
    </gazebo>
    <gazebo reference="J3">
        <material>Gazebo/White</material>
    </gazebo>
    <gazebo reference="J4">
        <material>Gazebo/White</material>
    </gazebo>
    <gazebo reference="J5">
        <material>Gazebo/White</material>
    </gazebo>
    <gazebo reference="J6">
        <material>Gazebo/White</material>
    </gazebo>
    <gazebo>
        <gravity>False</gravity>
    </gazebo>
    <joint name="joint_1" type="revolute">
        <parent link="base_link" />
        <child link="J1" />
        <origin rpy="0.000000 0.000000 0.000000" xyz="0.000000 0.000000 0.000000" />
        <axis xyz="-0.000000 -0.000000 1.000000" />
        <limit effort="100" lower="-2.96706" upper="2.96706" velocity="1" />
        <dynamics damping="0" friction="0" />
    </joint>
    <joint name="joint_2" type="revolute">
        <parent link="J1" />
        <child link="J2" />
        <origin rpy="0.000000 0.000000 0.000000" xyz="0.075000 0.000000 0.335000" />
        <axis xyz="-0.000000 1.000000 -0.000000" />
        <limit effort="100" lower="-1.745329" upper="2.356194" velocity="1" />
        <dynamics damping="0" friction="0" />
    </joint>
    <joint name="joint_3" type="revolute">
        <parent link="J2" />
        <child link="J3" />
        <origin rpy="0.000000 0.000000 0.000000" xyz="0.000000 0.000000 0.365000" />
        <axis xyz="-0.000000 1.000000 -0.000000" />
        <limit effort="100" lower="-2.076942" upper="2.949606" velocity="1" />
        <dynamics damping="0" friction="0" />
    </joint>
    <joint name="joint_4" type="revolute">
        <parent link="J3" />
        <child link="J4" />
        <origin rpy="0.000000 0.000000 0.000000" xyz="-0.090000 0.000000 -0.700000" />
        <axis xyz="-0.000000 -0.000000 1.000000" />
        <limit effort="100" lower="-3.316126" upper="3.316126" velocity="1" />
        <dynamics damping="0" friction="0" />
    </joint>
    <joint name="joint_5" type="revolute">
        <parent link="J4" />
        <child link="J5" />
        <origin rpy="0.000000 0.000000 0.000000" xyz="0.000000 0.000000 1.105000" />
        <axis xyz="-0.000000 1.000000 -0.000000" />
        <limit effort="100" lower="-2.094395" upper="2.094395" velocity="1" />
        <dynamics damping="0" friction="0" />
    </joint>
    <joint name="joint_6" type="revolute">
        <parent link="J5" />
        <child link="J6" />
        <origin rpy="0.000000 0.000000 0.000000" xyz="0.000000 0.000000 0.080000" />
        <axis xyz="-0.000000 -0.000000 1.000000" />
        <limit effort="100" lower="-6.283185" upper="6.283185" velocity="1" />
        <dynamics damping="0" friction="0" />
    </joint>
    <!--########### adding the gripper ########### -->
    <link name="gripper_base_link">
        <inertial>
            <origin rpy="0 0 0" xyz="-0.019922 7.2898E-05 0.077395" />
            <mass value="1.3258" />
            <inertia ixx="0.0035252" ixy="2.2645E-06" ixz="-3.673E-05" iyy="0.0042085" iyz="-5.1365E-06" izz="0.0020359" />
        </inertial>
        <visual>
            <origin rpy="0 0 0" xyz="0 0 0" />
            <geometry>
                <mesh filename="package://add_post_pro_simulation/mesh/gripper_base_link.STL" />
            </geometry>
            <material name="">
                <color rgba="0.79216 0.81961 0.93333 1" />
            </material>
        </visual>
        <collision>
            <origin rpy="0 0 0" xyz="0 0 0" />
            <geometry>
                <mesh filename="package://add_post_pro_simulation/mesh/gripper_base_link.STL" />
            </geometry>
        </collision>
    </link>

    <link name="gripper_Link">
        <inertial>
            <origin rpy="0 0 0" xyz="-0.0195 0.00014702 0.002743" />
            <mass value="0.027698" />
            <inertia ixx="9.9675E-06" ixy="7.5503E-08" ixz="-2.2624E-07" iyy="2.0524E-05" iyz="1.7057E-09" izz="2.7839E-05" />
        </inertial>
        <visual>
            <origin rpy="0 0 0" xyz="0 0 0" />
            <geometry>
                <mesh filename="package://add_post_pro_simulation/mesh/gripper_Link.STL" />
            </geometry>
            <material name="">
                <color rgba="1 1 1 1" />
            </material>
        </visual>
        <!-- <collision>
            <origin rpy="0 0 0" xyz="0 0 0" />
            <geometry>
                <mesh filename="package://add_post_pro_simulation/mesh/gripper_Link.STL" />
            </geometry>
        </collision> -->
    </link>

    <joint name="gripper_base_Joint" type="fixed">
        <origin rpy="0 0 3.14" xyz="0 0 0.004" />
        <parent link="J6" />
        <child link="gripper_base_link" />
        <axis xyz="0 0 -1" />
    </joint>

    <joint name="gripper_Joint" type="prismatic">
        <origin rpy="0 0 0.0" xyz="0 0 0.02565" />
        <parent link="gripper_base_link" />
        <child link="gripper_Link" />
        <axis xyz="0 0 -1" />
        <limit effort="1" lower="0" upper="0.021" velocity="1" />
    </joint>

    <gazebo reference="gripper_base_link">
		<material>Gazebo/Gray</material>
	</gazebo>
	<gazebo reference="gripper_Link">
		<material>Gazebo/Gray</material>
	</gazebo>
    <!--########### end of adding the gripper ########### -->
    
    
</robot>

