<?xml version="1.0" ?>
<robot name="linear_actuator" xmlns:xacro="http://www.ros.org/wiki/xacro">
 <!--
 <xacro:macro name="linear_actuator" params="parent *origin"> 


	<link name="world">
	</link>

	<joint name="joint_w" type="fixed">
		<parent link="world"/>
		<child link="base_link"/>
		<origin xyz="0 0 0"/>
	</joint>

	<link name="base_link">
		<visual>
			<origin rpy="0 0 0" xyz="0 0 0"/>
			<geometry>
				<mesh filename="package://add_post_pro_robot/meshes/LinActBase.dae" scale="1 1 1"/>
			</geometry>
		</visual>
		<collision>
			<origin rpy="0 0 0" xyz="0 0 0"/>
			<geometry>
				<mesh filename="package://add_post_pro_robot/meshes/LinActBase.dae" scale="1 1 1"/>
			</geometry>
		</collision>
		<inertial>
			<mass value="1"/>
			<origin rpy="0.000000 0.000000 0.000000" xyz="0.000000 0.000000 0.000000"/>
			<inertia ixx="1" ixy="0" ixz="0" iyy="1" iyz="0" izz="1"/>
		</inertial>
	</link>

	<link name="slider">
		<visual>
			<origin rpy="0 0 0" xyz="0 0 0"/>
			<geometry>
				<mesh filename="package://add_post_pro_robot/meshes/LinActSlider.dae" scale="1 1 1"/>
			</geometry>
		</visual>
		<collision>
			<origin rpy="0 0 0" xyz="0 0 0"/>
			<geometry>
				<mesh filename="package://add_post_pro_robot/meshes/LinActSlider.dae" scale="1 1 1"/>
			</geometry>
		</collision>
		<inertial>
			<mass value="1"/>
			<origin rpy="0.000000 0.000000 0.000000" xyz="0.000000 0.000000 0.000000"/>
			<inertia ixx="1" ixy="0" ixz="0" iyy="1" iyz="0" izz="1"/>
		</inertial>
	</link>

	<gazebo reference="base_link">
		<material>Gazebo/CoM</material>
	</gazebo>
	<gazebo reference="slider">
		<material>Gazebo/Gray</material>
	</gazebo>

	<gazebo>
		<gravity>False</gravity>
	</gazebo>
	<joint name="joint_1" type="prismatic">
		<parent link="base_link"/>
		<child link="slider"/>
		<origin rpy="0.000000 0.000000 0.000000" xyz="0.000000 0.000000 0.000000"/>
		<axis xyz="-0.000000 -0.000000 1.000000"/>
		<limit effort="100" lower="-2.96706" upper="2.96706" velocity="1"/>
		<dynamics damping="0" friction="0"/>
	</joint>



	<gazebo>
        <plugin name="gazebo_ros_control" filename="libgazebo_ros_control.so">
            <robotNamespace>/</robotNamespace>
        </plugin>
    </gazebo>

</xacro:macro>
</robot>
-->



 	<xacro:macro name="linear_actuator" params="parent *origin"> 
 
		<link name="actuator_base">
			<visual>
				<origin rpy="0 0 0" xyz="0 0 0" />
				<geometry>
					<box size = "0.6 0.2 0.1" />
				</geometry>
			</visual>
			<collision>
				<origin rpy="0 0 0" xyz="0 0 0" />
				<geometry>
					<box size="0.6 0.1 0.2" />
				</geometry>
			</collision>

			<inertial>
				<origin rpy="0 0 0" xyz="0 0 0" />
				<mass value="1" />
				<inertia ixx="100" ixy="0" ixz="0" iyy="100" iyz="0" izz="100" />
			</inertial>
		</link>

		<joint name="linear_prismatic_joint" type="continuous">
			<parent link="actuator_base" />
			<child link="linear_stage" />
			<origin rpy="0.000000 0.000000 0.000000" xyz="0.000000 0.000000 .16" />
			<limit effort="1000.0" lower="-6.28" upper="6.28" velocity="0.5"/>
			<limit effort="1000.0" velocity="0.5" />
			<axis xyz="0 0 1" />
		</joint>

		<link name="linear_stage">
			<visual>
				<origin rpy="0 0 0" xyz="0 0 0.1" />
				<geometry>
					<box size = "0.3 0.08 0.15" />
				</geometry>
			</visual>
			<collision>
				<origin rpy="0 0 0" xyz="0 0 0" />
				<geometry>
					<box size="0.3 0.08 0.15" />
				</geometry>
			</collision>

			<inertial>
				<origin rpy="0 0 0" xyz="0 0 0" />
				<mass value="1" />
				<inertia ixx="100" ixy="0" ixz="0" iyy="100" iyz="0" izz="100" />
			</inertial>
		</link>

	</xacro:macro>

</robot>

