<?xml version="1.0" encoding="utf-8"?>
<!-- =================================================================================== -->
<!-- |    This document was autogenerated by xacro from linear_actuator.urdf.xacro     | -->
<!-- |    EDITING THIS FILE BY HAND IS NOT RECOMMENDED                                 | -->
<!-- =================================================================================== -->
<robot name="linear_actuator">
  <material name="red">
    <color rgba="0.8 0 0 1"/>
  </material>
  <material name="blue">
    <color rgba="0 0 0.8 1"/>
  </material>
  <material name="white">
    <color rgba="1 1 1 1"/>
  </material>
  <material name="black">
    <color rgba="0 0 0 1"/>
  </material>
  <link name="world">
		</link>
  <joint name="joint_w" type="fixed">
    <parent link="world"/>
    <child link="actuator_base"/>
    <origin xyz="0 0 0"/>
  </joint>
  <link name="actuator_base">
    <visual>
      <origin rpy="0 0 0" xyz="0 0 0.02"/>
      <geometry>
        <box size="0.37 0.05 0.04"/>
        <!-- <mesh filename="package://add_post_pro_robot/meshes/LinActBase.dae" scale="0.01 0.01 0.01"/> -->
      </geometry>
      <material name="white"/>
    </visual>
    <collision>
      <origin rpy="0 0 0" xyz="0 0 0.02"/>
      <geometry>
        <box size="0.37 0.05 0.04"/>
        <!-- <mesh filename="package://add_post_pro_robot/meshes/LinActBase.dae" scale="0.01 0.01 0.01"/> -->
      </geometry>
    </collision>
    <inertial>
      <origin rpy="0 0 0" xyz="0 0 0"/>
      <mass value="1"/>
      <inertia ixx="100" ixy="0" ixz="0" iyy="100" iyz="0" izz="100"/>
    </inertial>
  </link>
  <joint name="linear_prismatic_joint" type="prismatic">
    <parent link="actuator_base"/>
    <child link="linear_stage"/>
    <origin rpy="0 0 0" xyz="0 0 0"/>
    <limit effort="1000.0" lower="-6.28" upper="6.28" velocity="0.5"/>
    <limit effort="1000.0" velocity="0.5"/>
    <axis xyz="1 0 0"/>
    <limit lower="-0.155" upper="0.155"/>
  </joint>
  <link name="linear_stage">
    <visual>
      <origin rpy="0 0 0" xyz="0 0 0.06"/>
      <geometry>
        <box size="0.06 0.05 0.04"/>
        <!-- <mesh filename="package://add_post_pro_robot/meshes/LinActSlider.dae" scale="0.01 0.01 0.01"/> -->
      </geometry>
      <material name="blue"/>
    </visual>
    <collision>
      <origin rpy="0 0 0" xyz="0 0 0.06"/>
      <geometry>
        <box size="0.06 0.05 0.04"/>
        <!-- <mesh filename="package://add_post_pro_robot/meshes/LinActSlider.dae" scale="0.01 0.01 0.01"/> -->
      </geometry>
    </collision>
    <inertial>
      <origin rpy="0 0 0" xyz="0 0 0"/>
      <mass value="1"/>
      <inertia ixx="100" ixy="0" ixz="0" iyy="100" iyz="0" izz="100"/>
    </inertial>
  </link>
  <gazebo>
    <plugin filename="libgazebo_ros_control.so" name="gazebo_ros_control">
      <robotNamespace>/</robotNamespace>
    </plugin>
  </gazebo>
</robot>
