<?xml version="1.0" ?>
<!-- =================================================================================== -->
<!-- |    This document was autogenerated by xacro from /home/tomasz/Projects/add_post_pro/src/add_post_pro/add_post_pro_robot/urdf/add_post_pro_robot_b120.urdf.xacro | -->
<!-- |    EDITING THIS FILE BY HAND IS NOT RECOMMENDED                                 | -->
<!-- =================================================================================== -->
<robot name="add_post_pro_robot_b120" xmlns:xacro="http://www.ros.org/wiki/xacro">
    <transmission name="trans_1">
        <type>transmission_interface/SimpleTransmission</type>
        <joint name="joint_1">
            <hardwareInterface>hardware_interface/PositionJointInterface</hardwareInterface>
        </joint>
        <actuator name="motor_1">
            <hardwareInterface>hardware_interface/PositionJointInterface</hardwareInterface>
            <mechanicalReduction>1</mechanicalReduction>
        </actuator>
    </transmission>
    <transmission name="trans_2">
        <type>transmission_interface/SimpleTransmission</type>
        <joint name="joint_2">
            <hardwareInterface>hardware_interface/PositionJointInterface</hardwareInterface>
        </joint>
        <actuator name="motor_2">
            <hardwareInterface>hardware_interface/PositionJointInterface</hardwareInterface>
            <mechanicalReduction>1</mechanicalReduction>
        </actuator>
    </transmission>
    <transmission name="trans_3">
        <type>transmission_interface/SimpleTransmission</type>
        <joint name="joint_3">
            <hardwareInterface>hardware_interface/PositionJointInterface</hardwareInterface>
        </joint>
        <actuator name="motor_3">
            <hardwareInterface>hardware_interface/PositionJointInterface</hardwareInterface>
            <mechanicalReduction>1</mechanicalReduction>
        </actuator>
    </transmission>
    <transmission name="trans_4">
        <type>transmission_interface/SimpleTransmission</type>
        <joint name="joint_4">
            <hardwareInterface>hardware_interface/PositionJointInterface</hardwareInterface>
        </joint>
        <actuator name="motor_4">
            <hardwareInterface>hardware_interface/PositionJointInterface</hardwareInterface>
            <mechanicalReduction>1</mechanicalReduction>
        </actuator>
    </transmission>
    <transmission name="trans_5">
        <type>transmission_interface/SimpleTransmission</type>
        <joint name="joint_5">
            <hardwareInterface>hardware_interface/PositionJointInterface</hardwareInterface>
        </joint>
        <actuator name="motor_5">
            <hardwareInterface>hardware_interface/PositionJointInterface</hardwareInterface>
            <mechanicalReduction>1</mechanicalReduction>
        </actuator>
    </transmission>
    <transmission name="trans_6">
        <type>transmission_interface/SimpleTransmission</type>
        <joint name="joint_6">
            <hardwareInterface>hardware_interface/PositionJointInterface</hardwareInterface>
        </joint>
        <actuator name="motor_6">
            <hardwareInterface>hardware_interface/PositionJointInterface</hardwareInterface>
            <mechanicalReduction>1</mechanicalReduction>
        </actuator>
    </transmission>
    <gazebo>
        <plugin filename="libgazebo_ros_control.so" name="gazebo_ros_control">
            <robotNamespace>/vs6577</robotNamespace>
            <legacyModeNS>true</legacyModeNS>
        </plugin>
    </gazebo>
    <link name="world" />
    <joint name="joint_w" type="fixed">
        <parent link="world" />
        <child link="base_link" />
        <origin xyz="0 0 0" />
    </joint>
    <link name="base_link">
        <visual>
            <origin rpy="0 0 0" xyz="0 0 0" />
            <geometry>
                <mesh filename="package://denso_robot_descriptions/vs6577_description/meshes/base_link.dae" scale="1 1 1" />
            </geometry>
        </visual>
        <collision>
            <origin rpy="0 0 0" xyz="0 0 0" />
            <geometry>
                <mesh filename="package://denso_robot_descriptions/vs6577_description/meshes/base_link.dae" scale="1 1 1" />
            </geometry>
        </collision>
        
<inertial>
            <mass value="1" />
            <origin rpy="0.000000 0.000000 0.000000" xyz="0.000000 0.000000 0.000000" />
            <inertia ixx="1" ixy="0" ixz="0" iyy="1" iyz="0" izz="1" />
        </inertial>

    </link>
    <link name="J1">
        <visual>
            <origin rpy="0 0 0" xyz="0 0 0" />
            <geometry>
                <mesh filename="package://denso_robot_descriptions/vs6577_description/meshes/J1.dae" scale="1 1 1" />
            </geometry>
        </visual>
        <collision>
            <origin rpy="0 0 0" xyz="0 0 0" />
            <geometry>
                <mesh filename="package://denso_robot_descriptions/vs6577_description/meshes/J1.dae" scale="1 1 1" />
            </geometry>
        </collision>
        
<inertial>
            <mass value="1" />
            <origin rpy="0.000000 0.000000 0.000000" xyz="0.000000 0.000000 0.000000" />
            <inertia ixx="1" ixy="0" ixz="0" iyy="1" iyz="0" izz="1" />
        </inertial>

    </link>
    <link name="J2">
        <visual>
            <origin rpy="0 0 0" xyz="0 0 0" />
            <geometry>
                <mesh filename="package://denso_robot_descriptions/vs6577_description/meshes/J2.dae" scale="1 1 1" />
            </geometry>
        </visual>
        <collision>
            <origin rpy="0 0 0" xyz="0 0 0" />
            <geometry>
                <mesh filename="package://denso_robot_descriptions/vs6577_description/meshes/J2.dae" scale="1 1 1" />
            </geometry>
        </collision>
        
<inertial>
            <mass value="1" />
            <origin rpy="0.000000 0.000000 0.000000" xyz="0.000000 0.000000 0.000000" />
            <inertia ixx="1" ixy="0" ixz="0" iyy="1" iyz="0" izz="1" />
        </inertial>

    </link>
    <link name="J3">
        <visual>
            <origin rpy="0 0 0" xyz="0 0 0" />
            <geometry>
                <mesh filename="package://denso_robot_descriptions/vs6577_description/meshes/J3.dae" scale="1 1 1" />
            </geometry>
        </visual>
        <collision>
            <origin rpy="0 0 0" xyz="0 0 0" />
            <geometry>
                <mesh filename="package://denso_robot_descriptions/vs6577_description/meshes/J3.dae" scale="1 1 1" />
            </geometry>
        </collision>
        
<inertial>
            <mass value="1" />
            <origin rpy="0.000000 0.000000 0.000000" xyz="0.000000 0.000000 0.000000" />
            <inertia ixx="1" ixy="0" ixz="0" iyy="1" iyz="0" izz="1" />
        </inertial>

    </link>
    <link name="J4">
        <visual>
            <origin rpy="0 0 0" xyz="0 0 0" />
            <geometry>
                <mesh filename="package://denso_robot_descriptions/vs6577_description/meshes/J4.dae" scale="1 1 1" />
            </geometry>
        </visual>
        <collision>
            <origin rpy="0 0 0" xyz="0 0 0" />
            <geometry>
                <mesh filename="package://denso_robot_descriptions/vs6577_description/meshes/J4.dae" scale="1 1 1" />
            </geometry>
        </collision>
        
<inertial>
            <mass value="1" />
            <origin rpy="0.000000 0.000000 0.000000" xyz="0.000000 0.000000 0.000000" />
            <inertia ixx="1" ixy="0" ixz="0" iyy="1" iyz="0" izz="1" />
        </inertial>

    </link>
    <link name="J5">
        <visual>
            <origin rpy="0 0 0" xyz="0 0 0" />
            <geometry>
                <mesh filename="package://denso_robot_descriptions/vs6577_description/meshes/J5.dae" scale="1 1 1" />
            </geometry>
        </visual>
        <collision>
            <origin rpy="0 0 0" xyz="0 0 0" />
            <geometry>
                <mesh filename="package://denso_robot_descriptions/vs6577_description/meshes/J5.dae" scale="1 1 1" />
            </geometry>
        </collision>
        
<inertial>
            <mass value="1" />
            <origin rpy="0.000000 0.000000 0.000000" xyz="0.000000 0.000000 0.000000" />
            <inertia ixx="1" ixy="0" ixz="0" iyy="1" iyz="0" izz="1" />
        </inertial>

    </link>
    <link name="J6">
        <visual>
            <origin rpy="0 0 0" xyz="0 0 0" />
            <geometry>
                <mesh filename="package://denso_robot_descriptions/vs6577_description/meshes/J6.dae" scale="1 1 1" />
            </geometry>
        </visual>
        <collision>
            <origin rpy="0 0 0" xyz="0 0 0" />
            <geometry>
                <mesh filename="package://denso_robot_descriptions/vs6577_description/meshes/J6.dae" scale="1 1 1" />
            </geometry>
        </collision>
        
<inertial>
            <mass value="1" />
            <origin rpy="0.000000 0.000000 0.000000" xyz="0.000000 0.000000 0.000000" />
            <inertia ixx="1" ixy="0" ixz="0" iyy="1" iyz="0" izz="1" />
        </inertial>

    </link>
    <gazebo reference="base_link">
        <material>Gazebo/CoM</material>
    </gazebo>
    <gazebo reference="J1">
        <material>Gazebo/Gray</material>
    </gazebo>
    <gazebo reference="J2">
        <material>Gazebo/Gray</material>
    </gazebo>
    <gazebo reference="J3">
        <material>Gazebo/Gray</material>
    </gazebo>
    <gazebo reference="J4">
        <material>Gazebo/Gray</material>
    </gazebo>
    <gazebo reference="J5">
        <material>Gazebo/Gray</material>
    </gazebo>
    <gazebo reference="J6">
        <material>Gazebo/Gray</material>
    </gazebo>
    <gazebo reference="EEF_tool_mount">
        <material>Gazebo/CoM</material>
    </gazebo>
    <gazebo>
        <gravity>False</gravity>
    </gazebo>
    <joint name="joint_1" type="revolute">
        <parent link="base_link" />
        <child link="J1" />
        <origin rpy="0.000000 0.000000 0.000000" xyz="0.000000 0.000000 0.000000" />
        <axis xyz="-0.000000 -0.000000 1.000000" />
        <limit effort="100" lower="-2.96706" upper="2.96706" velocity="1" />
        <dynamics damping="0" friction="0" />
    </joint>
    <joint name="joint_2" type="revolute">
        <parent link="J1" />
        <child link="J2" />
        <origin rpy="0.000000 0.000000 0.000000" xyz="0.075000 0.000000 0.335000" />
        <axis xyz="-0.000000 1.000000 -0.000000" />
        <limit effort="100" lower="-1.745329" upper="2.356194" velocity="1" />
        <dynamics damping="0" friction="0" />
    </joint>
    <joint name="joint_3" type="revolute">
        <parent link="J2" />
        <child link="J3" />
        <origin rpy="0.000000 0.000000 0.000000" xyz="0.000000 0.000000 0.365000" />
        <axis xyz="-0.000000 1.000000 -0.000000" />
        <limit effort="100" lower="-2.076942" upper="2.949606" velocity="1" />
        <dynamics damping="0" friction="0" />
    </joint>
    <joint name="joint_4" type="revolute">
        <parent link="J3" />
        <child link="J4" />
        <origin rpy="0.000000 0.000000 0.000000" xyz="-0.090000 0.000000 -0.700000" />
        <axis xyz="-0.000000 -0.000000 1.000000" />
        <limit effort="100" lower="-3.316126" upper="3.316126" velocity="1" />
        <dynamics damping="0" friction="0" />
    </joint>
    <joint name="joint_5" type="revolute">
        <parent link="J4" />
        <child link="J5" />
        <origin rpy="0.000000 0.000000 0.000000" xyz="0.000000 0.000000 1.105000" />
        <axis xyz="-0.000000 1.000000 -0.000000" />
        <limit effort="100" lower="-2.094395" upper="2.094395" velocity="1" />
        <dynamics damping="0" friction="0" />
    </joint>
    <joint name="joint_6" type="revolute">
        <parent link="J5" />
        <child link="J6" />
        <origin rpy="0.000000 0.000000 0.000000" xyz="0.000000 0.000000 0.080000" />
        <axis xyz="-0.000000 -0.000000 1.000000" />
        <limit effort="100" lower="-6.283185" upper="6.283185" velocity="1" />
        <dynamics damping="0" friction="0" />
    </joint>
    <link name="EEF_tool_mount">
        <visual>
            <origin rpy="0.000000 0 0" xyz="0 0 0" />
            <geometry>
                <mesh filename="package://add_post_pro_robot/meshes/tool_mount.stl" scale=".001 .001 .001" />
            </geometry>
        </visual>
        <collision>
            <origin rpy="0.000000 0 0" xyz="0 0 0" />
            <geometry>
                <mesh filename="package://add_post_pro_robot/meshes/tool_mount.stl" scale=".001 .001 .001" />
            </geometry>
        </collision>
        
<inertial>
            <mass value="1" />
            <origin rpy="0.000000 0.000000 0.000000" xyz="0.000000 0.000000 0.000000" />
            <inertia ixx="1" ixy="0" ixz="0" iyy="1" iyz="0" izz="1" />
        </inertial>

    </link>
    <link name="EEF_sensor_holder">
        <visual>
            <origin rpy="0 0 0" xyz="0 0 0" />
            <geometry>
                <mesh filename="package://add_post_pro_robot/meshes/multisensor_holder_origin.stl" scale=".001 .001 .001" />
            </geometry>
        </visual>
        <collision>
            <origin rpy="0 0 0" xyz="0 0 0" />
            <geometry>
                <mesh filename="package://add_post_pro_robot/meshes/multisensor_holder_origin.stl" scale=".001 .001 .001" />
            </geometry>
        </collision>
        
<inertial>
            <mass value="1" />
            <origin rpy="0.000000 0.000000 0.000000" xyz="0.000000 0.000000 0.000000" />
            <inertia ixx="1" ixy="0" ixz="0" iyy="1" iyz="0" izz="1" />
        </inertial>

    </link>
    <link name="EEF_scanner" />
    <link name="EEF_depstech_camera" />
    <joint name="end_effector_mount" type="fixed">
        <parent link="J6" />
        <child link="EEF_tool_mount" />
        <origin rpy="0.000000 0.000000 0.000000" xyz="0.000000 0.000000 0.000000" />
    </joint>
    <joint name="end_effector_magnet" type="fixed">
        <parent link="J6" />
        <child link="EEF_sensor_holder" />
        <origin rpy="0.000000 0.000000 3.14159265359" xyz="0.000000 0.000000 0.000000" />
    </joint>
    <joint name="end_effector_scanner_holder" type="fixed">
        <parent link="EEF_sensor_holder" />
        <child link="EEF_scanner" />
        <origin rpy="0.000000 3.14159265359 1.57079632679" xyz="0.000000 0.091600 0.005500" />
    </joint>
    <joint name="end_effector_depstech_holder" type="fixed">
        <parent link="EEF_sensor_holder" />
        <child link="EEF_depstech_camera" />
        <origin rpy="0.392699081699 -0.785398163397 -0.795339912301" xyz="-0.042000 0.0353000 0.19000" />
    </joint>
    <!-- Camera link -->
    <link name="D415_camera">
        <visual>
            <origin rpy="1.57079632679 0 1.57079632679" xyz="0 0 0" />
            <geometry>
                <mesh filename="package://realsense_cam/meshes/simplified_d415.stl" />
            </geometry>
        </visual>
        <collision>
            <geometry>
                <box size="0.0078 0.130 0.0192" />
            </geometry>
        </collision>
        
<inertial>
            <mass value="0.0615752" />
            <origin rpy="0 0 0" xyz="0 0 0" />
            <inertia ixx="9.108e-05" ixy="0" ixz="0" iyy="2.51e-06" iyz="0" izz="8.931e-05" />
        </inertial>

    </link>
    <!-- Connect camera to parent frame-->
    <joint name="realsense_joint" type="fixed">
        <parent link="EEF_sensor_holder" />
        <child link="D415_camera" />
        <origin rpy="0 -1.57079632679 3.14159265359" xyz=".075 0.001 .031" />
    </joint>
    <!-- Virtual links representing the cameras positons and orientations-->
    <link name="D415_color_optical_frame" />
    <link name="D415_depth_optical_frame" />
    <link name="D415_ired1_optical_frame" />
    <link name="D415_ired2_optical_frame" />
    <!-- Joints positioning the virtual links with respect to the camera main link-->
    <joint name="color_joint" type="fixed">
        <parent link="D415_camera" />
        <child link="D415_color_optical_frame" />
        <!-- <origin xyz="0 -0.046 0.004" rpy="0 0 0"/> -->
        <!-- The default position is change since in Rviz the cloud depth axis is Z not X-->
        <origin rpy="1.57079632679 3.14159265359 1.57079632679" xyz="0 0 0 " />
    </joint>
    <joint name="depth_joint" type="fixed">
        <parent link="D415_camera" />
        <child link="D415_depth_optical_frame" />
        <origin rpy="0 0 0" xyz="0 0 0" />
    </joint>
    <joint name="ired1_joint" type="fixed">
        <parent link="D415_camera" />
        <child link="D415_ired1_optical_frame" />
        <origin rpy="0 0 0" xyz="0 0 0" />
    </joint>
    <joint name="ired2_joint" type="fixed">
        <parent link="D415_camera" />
        <child link="D415_ired2_optical_frame" />
        <origin rpy="0 0 0" xyz="0 -0.055 0" />
    </joint>
    <!-- **********************************************************-->
    <!-- GAZEBO DEFINITIONS ***************************************-->
    <!-- Load plugin to the model ("robot" in urdf format)-->
    <gazebo>
        <plugin filename="librealsense_gazebo_plugin.so" name="D415" />
        <!--<pose frame="">0 0 0.015 0 0 0</pose>-->
    </gazebo>
    <!-- Load parameters to model's main link-->
    <gazebo reference="D415_camera">
        <self_collide>0</self_collide>
        <enable_wind>0</enable_wind>
        <kinematic>0</kinematic>
        <gravity>1</gravity>
        <!--<mu>1</mu>-->
        <mu2>1</mu2>
        <fdir1>0 0 0</fdir1>
        <!--<slip1>0</slip1>
        <slip2>0</slip2>-->
        <kp>1e+13</kp>
        <kd>1</kd>
        <!--<max_vel>0.01</max_vel>
        <min_depth>0</min_depth>-->
        <sensor name="D415_color_optical_frame" type="camera">
            <frameName>D415_color_optical_frame</frameName>
            <pose frame="">0 0 0 0 0 0</pose>
            <camera name="D415_camera">
                <horizontal_fov>1.211259</horizontal_fov>
                <image>
                    <width>1280</width>
                    <height>720</height>
                    <format>RGB_INT8</format>
                </image>
                <clip>
                    <near>0.1</near>
                    <far>100</far>
                </clip>
                <noise>
                    <type>gaussian</type>
                    <mean>0.0</mean>
                    <stddev>0.007</stddev>
                </noise>
            </camera>
            <always_on>1</always_on>
            <update_rate>60</update_rate>
            <visualize>1</visualize>
        </sensor>
        <sensor name="D415_ired1_optical_frame" type="camera">
            <frameName>D415_ired1_optical_frame</frameName>
            <pose frame="">0 0 0 0 0 0</pose>
            <camera name="D415_camera">
                <horizontal_fov>1.047</horizontal_fov>
                <image>
                    <width>1280</width>
                    <height>720</height>
                    <format>L_INT8</format>
                </image>
                <clip>
                    <near>0.1</near>
                    <far>100</far>
                </clip>
                <noise>
                    <type>gaussian</type>
                    <mean>0.0</mean>
                    <stddev>0.05</stddev>
                </noise>
            </camera>
            <always_on>1</always_on>
            <update_rate>60</update_rate>
            <visualize>0</visualize>
        </sensor>
        <sensor name="D415_ired2_optical_frame" type="camera">
            <frameName>D415_ired2_optical_frame</frameName>
            <pose frame="">0 -0.055 0 0 0</pose>
            <camera name="D415_camera">
                <horizontal_fov>1.047</horizontal_fov>
                <image>
                    <width>1280</width>
                    <height>720</height>
                    <format>L_INT8</format>
                </image>
                <clip>
                    <near>0.1</near>
                    <far>100</far>
                </clip>
                <noise>
                    <type>gaussian</type>
                    <mean>0.0</mean>
                    <stddev>0.05</stddev>
                </noise>
            </camera>
            <always_on>1</always_on>
            <update_rate>60</update_rate>
            <visualize>0</visualize>
        </sensor>
        <sensor name="D415_depth_optical_frame" type="depth">
            <pose frame="">0 0 0 0 0 0</pose>
            <camera name="D415_camera">
                <frameName>D415_depth_optical_frame</frameName>
                <horizontal_fov>1.13446</horizontal_fov>
                <image>
                    <width>1280</width>
                    <height>720</height>
                </image>
                <clip>
                    <near>0.1</near>
                    <far>100</far>
                </clip>
                <noise>
                    <type>gaussian</type>
                    <mean>0.0</mean>
                    <stddev>0.100</stddev>
                </noise>
            </camera>
            <always_on>1</always_on>
            <update_rate>60</update_rate>
            <visualize>0</visualize>
        </sensor>
    </gazebo>
    <!-- DONE -->
    <!-- Scanner link -->
    <link name="EEF_scancontrol">
        <visual>
            <origin rpy="0 0 0" xyz="0 0 0" />
            <geometry>
                <mesh filename="package://add_post_pro_robot/meshes/scancontrol2900.stl" scale=".001 .001 .001" />
            </geometry>
        </visual>
        <collision>
            <origin rpy="0 0 0" xyz="0 0 0" />
            <geometry>
                <mesh filename="package://add_post_pro_robot/meshes/scancontrol2900_collision.stl" scale=".001 .001 .001" />
            </geometry>
        </collision>
        
<inertial>
            <mass value="1" />
            <origin rpy="0.000000 0.000000 0.000000" xyz="0.000000 0.000000 0.000000" />
            <inertia ixx="1" ixy="0" ixz="0" iyy="1" iyz="0" izz="1" />
        </inertial>

    </link>
    <link name="scancontrol2900-50_laser" />
    <joint name="end_effector_scanner" type="fixed">
        <parent link="EEF_scanner" />
        <child link="EEF_scancontrol" />
        <origin rpy="0.000000 0.000000 0.000000" xyz="0.000000 0.000000 0.000000" />
    </joint>
    <joint name="laser_joint" type="fixed">
        <parent link="EEF_scancontrol" />
        <child link="scancontrol2900-50_laser" />
        <origin rpy="0 1.57079632679 -1.57079632679" xyz="0 -0.0324522 -.0761366" />
    </joint>
    <!-- <origin xyz="0 -0.0324522 -.0761366" rpy="${M_PI} ${M_PI/2} ${M_PI/2}"/> -->
    <gazebo reference="scancontrol2900-50_laser">
        <sensor name="scancontrol" type="gpu_ray">
            <pose>0 0 0 0 0 0</pose>
            <visualize>true</visualize>
            <update_rate>40</update_rate>
            <ray>
                <scan>
                    <horizontal>
                        <samples>1024</samples>
                        <resolution>1</resolution>
                        <min_angle>-0.392699081699</min_angle>
                        <max_angle>0.392699081699</max_angle>
                    </horizontal>
                </scan>
                <range>
                    <min>0.1</min>
                    <max>0.500</max>
                    <resolution>0.01</resolution>
                </range>
            </ray>
            <plugin filename="libgazebo_ros_gpu_laser.so" name="scancontrol_laser">
                <topicName>/arm/laser_scan</topicName>
                <frameName>scancontrol2900-50_laser</frameName>
            </plugin>
        </sensor>
    </gazebo>
    <link name="depstech_camera_link">
        <collision>
            <origin rpy="0 0 0" xyz="0 0 0" />
            <geometry>
                <cylinder length="0.02" radius="0.01" />
            </geometry>
        </collision>
        
<inertial>
            <mass value="1e-5" />
            <origin rpy="0 0 0" xyz="0 0 0" />
            <inertia ixx="1e-6" ixy="0" ixz="0" iyy="1e-6" iyz="0" izz="1e-6" />
        </inertial>

    </link>
    <joint name="camera_link_joint" type="fixed">
        <parent link="EEF_depstech_camera" />
        <child link="depstech_camera_link" />
        <origin rpy="0.000000 0.000000 0.000000" xyz="0.000000 0.000000 0.000000" />
    </joint>
    <!-- camera -->
    <gazebo reference="depstech_camera_link">
        <sensor name="depstech_camera" type="camera">
            <update_rate>30.0</update_rate>
            <camera name="depstech_camera">
                <horizontal_fov>1.3962634</horizontal_fov>
                <image>
                    <width>800</width>
                    <height>800</height>
                    <format>R8G8B8</format>
                </image>
                <clip>
                    <near>0.02</near>
                    <far>300</far>
                </clip>
                <noise>
                    <type>gaussian</type>
                    <!-- Noise is sampled independently per pixel on each frame.
               That pixel's noise value is added to each of its color
               channels, which at that point lie in the range [0,1]. -->
                    <mean>0.0</mean>
                    <stddev>0.007</stddev>
                </noise>
            </camera>
            <plugin filename="libgazebo_ros_camera.so" name="camera_controller">
                <alwaysOn>true</alwaysOn>
                <updateRate>0.0</updateRate>
                <cameraName>depstech_camera/camera/</cameraName>
                <imageTopicName>image_raw</imageTopicName>
                <cameraInfoTopicName>camera_info</cameraInfoTopicName>
                <frameName>depstech_camera_link</frameName>
                <hackBaseline>0.07</hackBaseline>
                <distortionK1>0.0</distortionK1>
                <distortionK2>0.0</distortionK2>
                <distortionK3>0.0</distortionK3>
                <distortionT1>0.0</distortionT1>
                <distortionT2>0.0</distortionT2>
            </plugin>
        </sensor>
    </gazebo>
    <gazebo reference="EEF_sensor_holder">
        <material>Gazebo/CoM</material>
    </gazebo>
    <gazebo reference="D415_camera">
        <material>Gazebo/CoM</material>
    </gazebo>
    <transmission name="trans_joint_1">
        <type>transmission_interface/SimpleTransmission</type>
        <joint name="joint_1">
            <hardwareInterface>hardware_interface/EffortJointInterface</hardwareInterface>
        </joint>
        <actuator name="joint_1_motor">
            <hardwareInterface>hardware_interface/EffortJointInterface</hardwareInterface>
            <mechanicalReduction>1</mechanicalReduction>
        </actuator>
    </transmission>
    <transmission name="trans_joint_2">
        <type>transmission_interface/SimpleTransmission</type>
        <joint name="joint_2">
            <hardwareInterface>hardware_interface/EffortJointInterface</hardwareInterface>
        </joint>
        <actuator name="joint_2_motor">
            <hardwareInterface>hardware_interface/EffortJointInterface</hardwareInterface>
            <mechanicalReduction>1</mechanicalReduction>
        </actuator>
    </transmission>
    <transmission name="trans_joint_3">
        <type>transmission_interface/SimpleTransmission</type>
        <joint name="joint_3">
            <hardwareInterface>hardware_interface/EffortJointInterface</hardwareInterface>
        </joint>
        <actuator name="joint_3_motor">
            <hardwareInterface>hardware_interface/EffortJointInterface</hardwareInterface>
            <mechanicalReduction>1</mechanicalReduction>
        </actuator>
    </transmission>
    <transmission name="trans_joint_4">
        <type>transmission_interface/SimpleTransmission</type>
        <joint name="joint_4">
            <hardwareInterface>hardware_interface/EffortJointInterface</hardwareInterface>
        </joint>
        <actuator name="joint_4_motor">
            <hardwareInterface>hardware_interface/EffortJointInterface</hardwareInterface>
            <mechanicalReduction>1</mechanicalReduction>
        </actuator>
    </transmission>
    <transmission name="trans_joint_5">
        <type>transmission_interface/SimpleTransmission</type>
        <joint name="joint_5">
            <hardwareInterface>hardware_interface/EffortJointInterface</hardwareInterface>
        </joint>
        <actuator name="joint_5_motor">
            <hardwareInterface>hardware_interface/EffortJointInterface</hardwareInterface>
            <mechanicalReduction>1</mechanicalReduction>
        </actuator>
    </transmission>
    <transmission name="trans_joint_6">
        <type>transmission_interface/SimpleTransmission</type>
        <joint name="joint_6">
            <hardwareInterface>hardware_interface/EffortJointInterface</hardwareInterface>
        </joint>
        <actuator name="joint_6_motor">
            <hardwareInterface>hardware_interface/EffortJointInterface</hardwareInterface>
            <mechanicalReduction>1</mechanicalReduction>
        </actuator>
    </transmission>
    <gazebo>
        <plugin name="gazebo_ros_control" filename="libgazebo_ros_control.so">
            <robotNamespace>/</robotNamespace>
        </plugin>
    </gazebo>
</robot>

<transmission name="trans_1">
        <type>transmission_interface/SimpleTransmission</type>
        <joint name="joint_1">
            <hardwareInterface>hardware_interface/PositionJointInterface</hardwareInterface>
        </joint>
        <actuator name="motor_1">
            <hardwareInterface>hardware_interface/PositionJointInterface</hardwareInterface>
            <mechanicalReduction>1</mechanicalReduction>
        </actuator>
    </transmission>
    <transmission name="trans_2">
        <type>transmission_interface/SimpleTransmission</type>
        <joint name="joint_2">
            <hardwareInterface>hardware_interface/PositionJointInterface</hardwareInterface>
        </joint>
        <actuator name="motor_2">
            <hardwareInterface>hardware_interface/PositionJointInterface</hardwareInterface>
            <mechanicalReduction>1</mechanicalReduction>
        </actuator>
    </transmission>
    <transmission name="trans_3">
        <type>transmission_interface/SimpleTransmission</type>
        <joint name="joint_3">
            <hardwareInterface>hardware_interface/PositionJointInterface</hardwareInterface>
        </joint>
        <actuator name="motor_3">
            <hardwareInterface>hardware_interface/PositionJointInterface</hardwareInterface>
            <mechanicalReduction>1</mechanicalReduction>
        </actuator>
    </transmission>
    <transmission name="trans_4">
        <type>transmission_interface/SimpleTransmission</type>
        <joint name="joint_4">
            <hardwareInterface>hardware_interface/PositionJointInterface</hardwareInterface>
        </joint>
        <actuator name="motor_4">
            <hardwareInterface>hardware_interface/PositionJointInterface</hardwareInterface>
            <mechanicalReduction>1</mechanicalReduction>
        </actuator>
    </transmission>
    <transmission name="trans_5">
        <type>transmission_interface/SimpleTransmission</type>
        <joint name="joint_5">
            <hardwareInterface>hardware_interface/PositionJointInterface</hardwareInterface>
        </joint>
        <actuator name="motor_5">
            <hardwareInterface>hardware_interface/PositionJointInterface</hardwareInterface>
            <mechanicalReduction>1</mechanicalReduction>
        </actuator>
    </transmission>
    <transmission name="trans_6">
        <type>transmission_interface/SimpleTransmission</type>
        <joint name="joint_6">
            <hardwareInterface>hardware_interface/PositionJointInterface</hardwareInterface>
        </joint>
        <actuator name="motor_6">
            <hardwareInterface>hardware_interface/PositionJointInterface</hardwareInterface>
            <mechanicalReduction>1</mechanicalReduction>
        </actuator>
    </transmission>
    <gazebo>
        <plugin filename="libgazebo_ros_control.so" name="gazebo_ros_control">
            <robotNamespace>/vs6577</robotNamespace>
            <legacyModeNS>true</legacyModeNS>
        </plugin>
    </gazebo>
    <link name="world" />
    <joint name="joint_w" type="fixed">
        <parent link="world" />
        <child link="base_link" />
        <origin xyz="0 0 0" />
    </joint>
    <link name="base_link">
        <visual>
            <origin rpy="0 0 0" xyz="0 0 0" />
            <geometry>
                <mesh filename="package://denso_robot_descriptions/vs6577_description/meshes/base_link.dae" scale="1 1 1" />
            </geometry>
        </visual>
        <collision>
            <origin rpy="0 0 0" xyz="0 0 0" />
            <geometry>
                <mesh filename="package://denso_robot_descriptions/vs6577_description/meshes/base_link.dae" scale="1 1 1" />
            </geometry>
        </collision>
        <inertial>
            <mass value="1" />
            <origin rpy="0.000000 0.000000 0.000000" xyz="0.000000 0.000000 0.000000" />
            <inertia ixx="1" ixy="0" ixz="0" iyy="1" iyz="0" izz="1" />
        </inertial>
    </link>
    <link name="J1">
        <visual>
            <origin rpy="0 0 0" xyz="0 0 0" />
            <geometry>
                <mesh filename="package://denso_robot_descriptions/vs6577_description/meshes/J1.dae" scale="1 1 1" />
            </geometry>
        </visual>
        <collision>
            <origin rpy="0 0 0" xyz="0 0 0" />
            <geometry>
                <mesh filename="package://denso_robot_descriptions/vs6577_description/meshes/J1.dae" scale="1 1 1" />
            </geometry>
        </collision>
        <inertial>
            <mass value="1" />
            <origin rpy="0.000000 0.000000 0.000000" xyz="0.000000 0.000000 0.000000" />
            <inertia ixx="1" ixy="0" ixz="0" iyy="1" iyz="0" izz="1" />
        </inertial>
    </link>
    <link name="J2">
        <visual>
            <origin rpy="0 0 0" xyz="0 0 0" />
            <geometry>
                <mesh filename="package://denso_robot_descriptions/vs6577_description/meshes/J2.dae" scale="1 1 1" />
            </geometry>
        </visual>
        <collision>
            <origin rpy="0 0 0" xyz="0 0 0" />
            <geometry>
                <mesh filename="package://denso_robot_descriptions/vs6577_description/meshes/J2.dae" scale="1 1 1" />
            </geometry>
        </collision>
        <inertial>
            <mass value="1" />
            <origin rpy="0.000000 0.000000 0.000000" xyz="0.000000 0.000000 0.000000" />
            <inertia ixx="1" ixy="0" ixz="0" iyy="1" iyz="0" izz="1" />
        </inertial>
    </link>
    <link name="J3">
        <visual>
            <origin rpy="0 0 0" xyz="0 0 0" />
            <geometry>
                <mesh filename="package://denso_robot_descriptions/vs6577_description/meshes/J3.dae" scale="1 1 1" />
            </geometry>
        </visual>
        <collision>
            <origin rpy="0 0 0" xyz="0 0 0" />
            <geometry>
                <mesh filename="package://denso_robot_descriptions/vs6577_description/meshes/J3.dae" scale="1 1 1" />
            </geometry>
        </collision>
        <inertial>
            <mass value="1" />
            <origin rpy="0.000000 0.000000 0.000000" xyz="0.000000 0.000000 0.000000" />
            <inertia ixx="1" ixy="0" ixz="0" iyy="1" iyz="0" izz="1" />
        </inertial>
    </link>
    <link name="J4">
        <visual>
            <origin rpy="0 0 0" xyz="0 0 0" />
            <geometry>
                <mesh filename="package://denso_robot_descriptions/vs6577_description/meshes/J4.dae" scale="1 1 1" />
            </geometry>
        </visual>
        <collision>
            <origin rpy="0 0 0" xyz="0 0 0" />
            <geometry>
                <mesh filename="package://denso_robot_descriptions/vs6577_description/meshes/J4.dae" scale="1 1 1" />
            </geometry>
        </collision>
        <inertial>
            <mass value="1" />
            <origin rpy="0.000000 0.000000 0.000000" xyz="0.000000 0.000000 0.000000" />
            <inertia ixx="1" ixy="0" ixz="0" iyy="1" iyz="0" izz="1" />
        </inertial>
    </link>
    <link name="J5">
        <visual>
            <origin rpy="0 0 0" xyz="0 0 0" />
            <geometry>
                <mesh filename="package://denso_robot_descriptions/vs6577_description/meshes/J5.dae" scale="1 1 1" />
            </geometry>
        </visual>
        <collision>
            <origin rpy="0 0 0" xyz="0 0 0" />
            <geometry>
                <mesh filename="package://denso_robot_descriptions/vs6577_description/meshes/J5.dae" scale="1 1 1" />
            </geometry>
        </collision>
        <inertial>
            <mass value="1" />
            <origin rpy="0.000000 0.000000 0.000000" xyz="0.000000 0.000000 0.000000" />
            <inertia ixx="1" ixy="0" ixz="0" iyy="1" iyz="0" izz="1" />
        </inertial>
    </link>
    <link name="J6">
        <visual>
            <origin rpy="0 0 0" xyz="0 0 0" />
            <geometry>
                <mesh filename="package://denso_robot_descriptions/vs6577_description/meshes/J6.dae" scale="1 1 1" />
            </geometry>
        </visual>
        <collision>
            <origin rpy="0 0 0" xyz="0 0 0" />
            <geometry>
                <mesh filename="package://denso_robot_descriptions/vs6577_description/meshes/J6.dae" scale="1 1 1" />
            </geometry>
        </collision>
        <inertial>
            <mass value="1" />
            <origin rpy="0.000000 0.000000 0.000000" xyz="0.000000 0.000000 0.000000" />
            <inertia ixx="1" ixy="0" ixz="0" iyy="1" iyz="0" izz="1" />
        </inertial>
    </link>
    <gazebo reference="base_link">
        <material>Gazebo/CoM</material>
    </gazebo>
    <gazebo reference="J1">
        <material>Gazebo/Gray</material>
    </gazebo>
    <gazebo reference="J2">
        <material>Gazebo/Gray</material>
    </gazebo>
    <gazebo reference="J3">
        <material>Gazebo/Gray</material>
    </gazebo>
    <gazebo reference="J4">
        <material>Gazebo/Gray</material>
    </gazebo>
    <gazebo reference="J5">
        <material>Gazebo/Gray</material>
    </gazebo>
    <gazebo reference="J6">
        <material>Gazebo/Gray</material>
    </gazebo>
    <gazebo reference="EEF_tool_mount">
        <material>Gazebo/CoM</material>
    </gazebo>
    <gazebo>
        <gravity>False</gravity>
    </gazebo>
    <joint name="joint_1" type="revolute">
        <parent link="base_link" />
        <child link="J1" />
        <origin rpy="0.000000 0.000000 0.000000" xyz="0.000000 0.000000 0.000000" />
        <axis xyz="-0.000000 -0.000000 1.000000" />
        <limit effort="100" lower="-2.96706" upper="2.96706" velocity="1" />
        <dynamics damping="0" friction="0" />
    </joint>
    <joint name="joint_2" type="revolute">
        <parent link="J1" />
        <child link="J2" />
        <origin rpy="0.000000 0.000000 0.000000" xyz="0.075000 0.000000 0.335000" />
        <axis xyz="-0.000000 1.000000 -0.000000" />
        <limit effort="100" lower="-1.745329" upper="2.356194" velocity="1" />
        <dynamics damping="0" friction="0" />
    </joint>
    <joint name="joint_3" type="revolute">
        <parent link="J2" />
        <child link="J3" />
        <origin rpy="0.000000 0.000000 0.000000" xyz="0.000000 0.000000 0.365000" />
        <axis xyz="-0.000000 1.000000 -0.000000" />
        <limit effort="100" lower="-2.076942" upper="2.949606" velocity="1" />
        <dynamics damping="0" friction="0" />
    </joint>
    <joint name="joint_4" type="revolute">
        <parent link="J3" />
        <child link="J4" />
        <origin rpy="0.000000 0.000000 0.000000" xyz="-0.090000 0.000000 -0.700000" />
        <axis xyz="-0.000000 -0.000000 1.000000" />
        <limit effort="100" lower="-3.316126" upper="3.316126" velocity="1" />
        <dynamics damping="0" friction="0" />
    </joint>
    <joint name="joint_5" type="revolute">
        <parent link="J4" />
        <child link="J5" />
        <origin rpy="0.000000 0.000000 0.000000" xyz="0.000000 0.000000 1.105000" />
        <axis xyz="-0.000000 1.000000 -0.000000" />
        <limit effort="100" lower="-2.094395" upper="2.094395" velocity="1" />
        <dynamics damping="0" friction="0" />
    </joint>
    <joint name="joint_6" type="revolute">
        <parent link="J5" />
        <child link="J6" />
        <origin rpy="0.000000 0.000000 0.000000" xyz="0.000000 0.000000 0.080000" />
        <axis xyz="-0.000000 -0.000000 1.000000" />
        <limit effort="100" lower="-6.283185" upper="6.283185" velocity="1" />
        <dynamics damping="0" friction="0" />
    </joint>
    <link name="EEF_tool_mount">
        <visual>
            <origin rpy="0.000000 0 0" xyz="0 0 0" />
            <geometry>
                <mesh filename="package://add_post_pro_robot/meshes/tool_mount.stl" scale=".001 .001 .001" />
            </geometry>
        </visual>
        <collision>
            <origin rpy="0.000000 0 0" xyz="0 0 0" />
            <geometry>
                <mesh filename="package://add_post_pro_robot/meshes/tool_mount.stl" scale=".001 .001 .001" />
            </geometry>
        </collision>
        <inertial>
            <mass value="1" />
            <origin rpy="0.000000 0.000000 0.000000" xyz="0.000000 0.000000 0.000000" />
            <inertia ixx="1" ixy="0" ixz="0" iyy="1" iyz="0" izz="1" />
        </inertial>
    </link>
    <link name="EEF_sensor_holder">
        <visual>
            <origin rpy="0 0 0" xyz="0 0 0" />
            <geometry>
                <mesh filename="package://add_post_pro_robot/meshes/multisensor_holder_origin.stl" scale=".001 .001 .001" />
            </geometry>
        </visual>
        <collision>
            <origin rpy="0 0 0" xyz="0 0 0" />
            <geometry>
                <mesh filename="package://add_post_pro_robot/meshes/multisensor_holder_origin.stl" scale=".001 .001 .001" />
            </geometry>
        </collision>
        <inertial>
            <mass value="1" />
            <origin rpy="0.000000 0.000000 0.000000" xyz="0.000000 0.000000 0.000000" />
            <inertia ixx="1" ixy="0" ixz="0" iyy="1" iyz="0" izz="1" />
        </inertial>
    </link>
    <link name="EEF_scanner" />
    <link name="EEF_depstech_camera" />
    <joint name="end_effector_mount" type="fixed">
        <parent link="J6" />
        <child link="EEF_tool_mount" />
        <origin rpy="0.000000 0.000000 0.000000" xyz="0.000000 0.000000 0.000000" />
    </joint>
    <joint name="end_effector_magnet" type="fixed">
        <parent link="J6" />
        <child link="EEF_sensor_holder" />
        <origin rpy="0.000000 0.000000 3.14159265359" xyz="0.000000 0.000000 0.000000" />
    </joint>
    <joint name="end_effector_scanner_holder" type="fixed">
        <parent link="EEF_sensor_holder" />
        <child link="EEF_scanner" />
        <origin rpy="0.000000 3.14159265359 1.57079632679" xyz="0.000000 0.091600 0.005500" />
    </joint>
    <joint name="end_effector_depstech_holder" type="fixed">
        <parent link="EEF_sensor_holder" />
        <child link="EEF_depstech_camera" />
        <origin rpy="0.392699081699 -0.785398163397 -0.795339912301" xyz="-0.042000 0.0353000 0.19000" />
    </joint>
    <!-- Camera link -->
    <link name="D415_camera">
        <visual>
            <origin rpy="1.57079632679 0 1.57079632679" xyz="0 0 0" />
            <geometry>
                <mesh filename="package://realsense_cam/meshes/simplified_d415.stl" />
            </geometry>
        </visual>
        <collision>
            <geometry>
                <box size="0.0078 0.130 0.0192" />
            </geometry>
        </collision>
        <inertial>
            <mass value="0.0615752" />
            <origin rpy="0 0 0" xyz="0 0 0" />
            <inertia ixx="9.108e-05" ixy="0" ixz="0" iyy="2.51e-06" iyz="0" izz="8.931e-05" />
        </inertial>
    </link>
    <!-- Connect camera to parent frame-->
    <joint name="realsense_joint" type="fixed">
        <parent link="EEF_sensor_holder" />
        <child link="D415_camera" />
        <origin rpy="0 -1.57079632679 3.14159265359" xyz=".075 0.001 .031" />
    </joint>
    <!-- Virtual links representing the cameras positons and orientations-->
    <link name="D415_color_optical_frame" />
    <link name="D415_depth_optical_frame" />
    <link name="D415_ired1_optical_frame" />
    <link name="D415_ired2_optical_frame" />
    <!-- Joints positioning the virtual links with respect to the camera main link-->
    <joint name="color_joint" type="fixed">
        <parent link="D415_camera" />
        <child link="D415_color_optical_frame" />
        <!-- <origin xyz="0 -0.046 0.004" rpy="0 0 0"/> -->
        <!-- The default position is change since in Rviz the cloud depth axis is Z not X-->
        <origin rpy="1.57079632679 3.14159265359 1.57079632679" xyz="0 0 0 " />
    </joint>
    <joint name="depth_joint" type="fixed">
        <parent link="D415_camera" />
        <child link="D415_depth_optical_frame" />
        <origin rpy="0 0 0" xyz="0 0 0" />
    </joint>
    <joint name="ired1_joint" type="fixed">
        <parent link="D415_camera" />
        <child link="D415_ired1_optical_frame" />
        <origin rpy="0 0 0" xyz="0 0 0" />
    </joint>
    <joint name="ired2_joint" type="fixed">
        <parent link="D415_camera" />
        <child link="D415_ired2_optical_frame" />
        <origin rpy="0 0 0" xyz="0 -0.055 0" />
    </joint>
    <!-- **********************************************************-->
    <!-- GAZEBO DEFINITIONS ***************************************-->
    <!-- Load plugin to the model ("robot" in urdf format)-->
    <gazebo>
        <plugin filename="librealsense_gazebo_plugin.so" name="D415" />
        <!--<pose frame="">0 0 0.015 0 0 0</pose>-->
    </gazebo>
    <!-- Load parameters to model's main link-->
    <gazebo reference="D415_camera">
        <self_collide>0</self_collide>
        <enable_wind>0</enable_wind>
        <kinematic>0</kinematic>
        <gravity>1</gravity>
        <!--<mu>1</mu>-->
        <mu2>1</mu2>
        <fdir1>0 0 0</fdir1>
        <!--<slip1>0</slip1>
        <slip2>0</slip2>-->
        <kp>1e+13</kp>
        <kd>1</kd>
        <!--<max_vel>0.01</max_vel>
        <min_depth>0</min_depth>-->
        <sensor name="D415_color_optical_frame" type="camera">
            <frameName>D415_color_optical_frame</frameName>
            <pose frame="">0 0 0 0 0 0</pose>
            <camera name="D415_camera">
                <horizontal_fov>1.211259</horizontal_fov>
                <image>
                    <width>1280</width>
                    <height>720</height>
                    <format>RGB_INT8</format>
                </image>
                <clip>
                    <near>0.1</near>
                    <far>100</far>
                </clip>
                <noise>
                    <type>gaussian</type>
                    <mean>0.0</mean>
                    <stddev>0.007</stddev>
                </noise>
            </camera>
            <always_on>1</always_on>
            <update_rate>60</update_rate>
            <visualize>1</visualize>
        </sensor>
        <sensor name="D415_ired1_optical_frame" type="camera">
            <frameName>D415_ired1_optical_frame</frameName>
            <pose frame="">0 0 0 0 0 0</pose>
            <camera name="D415_camera">
                <horizontal_fov>1.047</horizontal_fov>
                <image>
                    <width>1280</width>
                    <height>720</height>
                    <format>L_INT8</format>
                </image>
                <clip>
                    <near>0.1</near>
                    <far>100</far>
                </clip>
                <noise>
                    <type>gaussian</type>
                    <mean>0.0</mean>
                    <stddev>0.05</stddev>
                </noise>
            </camera>
            <always_on>1</always_on>
            <update_rate>60</update_rate>
            <visualize>0</visualize>
        </sensor>
        <sensor name="D415_ired2_optical_frame" type="camera">
            <frameName>D415_ired2_optical_frame</frameName>
            <pose frame="">0 -0.055 0 0 0</pose>
            <camera name="D415_camera">
                <horizontal_fov>1.047</horizontal_fov>
                <image>
                    <width>1280</width>
                    <height>720</height>
                    <format>L_INT8</format>
                </image>
                <clip>
                    <near>0.1</near>
                    <far>100</far>
                </clip>
                <noise>
                    <type>gaussian</type>
                    <mean>0.0</mean>
                    <stddev>0.05</stddev>
                </noise>
            </camera>
            <always_on>1</always_on>
            <update_rate>60</update_rate>
            <visualize>0</visualize>
        </sensor>
        <sensor name="D415_depth_optical_frame" type="depth">
            <pose frame="">0 0 0 0 0 0</pose>
            <camera name="D415_camera">
                <frameName>D415_depth_optical_frame</frameName>
                <horizontal_fov>1.13446</horizontal_fov>
                <image>
                    <width>1280</width>
                    <height>720</height>
                </image>
                <clip>
                    <near>0.1</near>
                    <far>100</far>
                </clip>
                <noise>
                    <type>gaussian</type>
                    <mean>0.0</mean>
                    <stddev>0.100</stddev>
                </noise>
            </camera>
            <always_on>1</always_on>
            <update_rate>60</update_rate>
            <visualize>0</visualize>
        </sensor>
    </gazebo>
    <!-- DONE -->
    <!-- Scanner link -->
    <link name="EEF_scancontrol">
        <visual>
            <origin rpy="0 0 0" xyz="0 0 0" />
            <geometry>
                <mesh filename="package://add_post_pro_robot/meshes/scancontrol2900.stl" scale=".001 .001 .001" />
            </geometry>
        </visual>
        <collision>
            <origin rpy="0 0 0" xyz="0 0 0" />
            <geometry>
                <mesh filename="package://add_post_pro_robot/meshes/scancontrol2900_collision.stl" scale=".001 .001 .001" />
            </geometry>
        </collision>
        <inertial>
            <mass value="1" />
            <origin rpy="0.000000 0.000000 0.000000" xyz="0.000000 0.000000 0.000000" />
            <inertia ixx="1" ixy="0" ixz="0" iyy="1" iyz="0" izz="1" />
        </inertial>
    </link>
    <link name="scancontrol2900-50_laser" />
    <joint name="end_effector_scanner" type="fixed">
        <parent link="EEF_scanner" />
        <child link="EEF_scancontrol" />
        <origin rpy="0.000000 0.000000 0.000000" xyz="0.000000 0.000000 0.000000" />
    </joint>
    <joint name="laser_joint" type="fixed">
        <parent link="EEF_scancontrol" />
        <child link="scancontrol2900-50_laser" />
        <origin rpy="0 1.57079632679 -1.57079632679" xyz="0 -0.0324522 -.0761366" />
    </joint>
    <!-- <origin xyz="0 -0.0324522 -.0761366" rpy="${M_PI} ${M_PI/2} ${M_PI/2}"/> -->
    <gazebo reference="scancontrol2900-50_laser">
        <sensor name="scancontrol" type="gpu_ray">
            <pose>0 0 0 0 0 0</pose>
            <visualize>true</visualize>
            <update_rate>40</update_rate>
            <ray>
                <scan>
                    <horizontal>
                        <samples>1024</samples>
                        <resolution>1</resolution>
                        <min_angle>-0.392699081699</min_angle>
                        <max_angle>0.392699081699</max_angle>
                    </horizontal>
                </scan>
                <range>
                    <min>0.1</min>
                    <max>0.500</max>
                    <resolution>0.01</resolution>
                </range>
            </ray>
            <plugin filename="libgazebo_ros_gpu_laser.so" name="scancontrol_laser">
                <topicName>/arm/laser_scan</topicName>
                <frameName>scancontrol2900-50_laser</frameName>
            </plugin>
        </sensor>
    </gazebo>
    <link name="depstech_camera_link">
        <collision>
            <origin rpy="0 0 0" xyz="0 0 0" />
            <geometry>
                <cylinder length="0.02" radius="0.01" />
            </geometry>
        </collision>
        <inertial>
            <mass value="1e-5" />
            <origin rpy="0 0 0" xyz="0 0 0" />
            <inertia ixx="1e-6" ixy="0" ixz="0" iyy="1e-6" iyz="0" izz="1e-6" />
        </inertial>
    </link>
    <joint name="camera_link_joint" type="fixed">
        <parent link="EEF_depstech_camera" />
        <child link="depstech_camera_link" />
        <origin rpy="0.000000 0.000000 0.000000" xyz="0.000000 0.000000 0.000000" />
    </joint>
    <!-- camera -->
    <gazebo reference="depstech_camera_link">
        <sensor name="depstech_camera" type="camera">
            <update_rate>30.0</update_rate>
            <camera name="depstech_camera">
                <horizontal_fov>1.3962634</horizontal_fov>
                <image>
                    <width>800</width>
                    <height>800</height>
                    <format>R8G8B8</format>
                </image>
                <clip>
                    <near>0.02</near>
                    <far>300</far>
                </clip>
                <noise>
                    <type>gaussian</type>
                    <!-- Noise is sampled independently per pixel on each frame.
               That pixel's noise value is added to each of its color
               channels, which at that point lie in the range [0,1]. -->
                    <mean>0.0</mean>
                    <stddev>0.007</stddev>
                </noise>
            </camera>
            <plugin filename="libgazebo_ros_camera.so" name="camera_controller">
                <alwaysOn>true</alwaysOn>
                <updateRate>0.0</updateRate>
                <cameraName>depstech_camera/camera/</cameraName>
                <imageTopicName>image_raw</imageTopicName>
                <cameraInfoTopicName>camera_info</cameraInfoTopicName>
                <frameName>depstech_camera_link</frameName>
                <hackBaseline>0.07</hackBaseline>
                <distortionK1>0.0</distortionK1>
                <distortionK2>0.0</distortionK2>
                <distortionK3>0.0</distortionK3>
                <distortionT1>0.0</distortionT1>
                <distortionT2>0.0</distortionT2>
            </plugin>
        </sensor>
    </gazebo>
    <gazebo reference="EEF_sensor_holder">
        <material>Gazebo/CoM</material>
    </gazebo>
    <gazebo reference="D415_camera">
        <material>Gazebo/CoM</material>
    </gazebo>
    <transmission name="trans_joint_1">
        <type>transmission_interface/SimpleTransmission</type>
        <joint name="joint_1">
            <hardwareInterface>hardware_interface/EffortJointInterface</hardwareInterface>
        </joint>
        <actuator name="joint_1_motor">
            <hardwareInterface>hardware_interface/EffortJointInterface</hardwareInterface>
            <mechanicalReduction>1</mechanicalReduction>
        </actuator>
    </transmission>
    <transmission name="trans_joint_2">
        <type>transmission_interface/SimpleTransmission</type>
        <joint name="joint_2">
            <hardwareInterface>hardware_interface/EffortJointInterface</hardwareInterface>
        </joint>
        <actuator name="joint_2_motor">
            <hardwareInterface>hardware_interface/EffortJointInterface</hardwareInterface>
            <mechanicalReduction>1</mechanicalReduction>
        </actuator>
    </transmission>
    <transmission name="trans_joint_3">
        <type>transmission_interface/SimpleTransmission</type>
        <joint name="joint_3">
            <hardwareInterface>hardware_interface/EffortJointInterface</hardwareInterface>
        </joint>
        <actuator name="joint_3_motor">
            <hardwareInterface>hardware_interface/EffortJointInterface</hardwareInterface>
            <mechanicalReduction>1</mechanicalReduction>
        </actuator>
    </transmission>
    <transmission name="trans_joint_4">
        <type>transmission_interface/SimpleTransmission</type>
        <joint name="joint_4">
            <hardwareInterface>hardware_interface/EffortJointInterface</hardwareInterface>
        </joint>
        <actuator name="joint_4_motor">
            <hardwareInterface>hardware_interface/EffortJointInterface</hardwareInterface>
            <mechanicalReduction>1</mechanicalReduction>
        </actuator>
    </transmission>
    <transmission name="trans_joint_5">
        <type>transmission_interface/SimpleTransmission</type>
        <joint name="joint_5">
            <hardwareInterface>hardware_interface/EffortJointInterface</hardwareInterface>
        </joint>
        <actuator name="joint_5_motor">
            <hardwareInterface>hardware_interface/EffortJointInterface</hardwareInterface>
            <mechanicalReduction>1</mechanicalReduction>
        </actuator>
    </transmission>
    <transmission name="trans_joint_6">
        <type>transmission_interface/SimpleTransmission</type>
        <joint name="joint_6">
            <hardwareInterface>hardware_interface/EffortJointInterface</hardwareInterface>
        </joint>
        <actuator name="joint_6_motor">
            <hardwareInterface>hardware_interface/EffortJointInterface</hardwareInterface>
            <mechanicalReduction>1</mechanicalReduction>
        </actuator>
    </transmission>
    <gazebo>
        <plugin name="gazebo_ros_control" filename="libgazebo_ros_control.so">
            <robotNamespace>/</robotNamespace>
        </plugin>
    </gazebo>
</robot>